Workbook
Name nom_projet: 'Hypotheses'!$B$5
Name pays: 'Hypotheses'!$B$6
Name devise: 'Hypotheses'!$B$7
Name clients_initiaux: 'Hypotheses'!$B$10
Name mois_lancement: 'Hypotheses'!$B$11
Name nouveaux_m1: 'Hypotheses'!$B$12
Name croissance_acquisition: 'Hypotheses'!$B$13
Name churn_mensuel: 'Hypotheses'!$B$14
Name hausse_prix_annuelle: 'Hypotheses'!$B$17
Name mois_debut_paiements: 'Hypotheses'!$B$18
Name part_boutiques_paiement: 'Hypotheses'!$B$19
Name volume_b2c_par_client: 'Hypotheses'!$B$20
Name taux_commission: 'Hypotheses'!$B$21
Name taux_tva: 'Hypotheses'!$B$24
Name part_ca_soumis_tva: 'Hypotheses'!$B$25
Name part_achats_avec_tva: 'Hypotheses'!$B$26
Name taux_is: 'Hypotheses'!$B$27
Name taux_minimum_is: 'Hypotheses'!$B$28
Name mois_paiement_is: 'Hypotheses'!$B$29
Name taux_charges_sociales: 'Hypotheses'!$B$30
Name infra_fixe: 'Hypotheses'!$B$33
Name infra_par_client: 'Hypotheses'!$B$34
Name taux_frais_paiement: 'Hypotheses'!$B$35
Name salaires_an1: 'Hypotheses'!$B$38
Name salaires_an2: 'Hypotheses'!$B$39
Name salaires_an3: 'Hypotheses'!$B$40
Name marketing_fixe: 'Hypotheses'!$B$41
Name cac: 'Hypotheses'!$B$42
Name outils_mensuels: 'Hypotheses'!$B$43
Name honoraires_mensuels: 'Hypotheses'!$B$44
Name autres_mensuelles: 'Hypotheses'!$B$45
Name frais_creation: 'Hypotheses'!$B$48
Name investissement_initial: 'Hypotheses'!$B$49
Name duree_amortissement: 'Hypotheses'!$B$50
Name apport_initial: 'Hypotheses'!$B$51
Name arpa_base: 'Hypotheses'!$B$58

Sheet Hypotheses
A1: Hypothèses — cellules bleues modifiables
A4: Projet
A5: Nom du projet | B5: WISHOP
A6: Pays de la structure | B6: Guinée équatoriale (autónomo, non assujetti à la TVA)
A7: Devise | B7: XAF
A9: Clients
A10: Clients payants au démarrage | B10: 0
A11: Mois du lancement commercial (1 = premier mois) | B11: 1
A12: Nouveaux clients le mois du lancement | B12: 5
A13: Croissance mensuelle des nouveaux clients | B13: 0.05
A14: Churn mensuel (clients perdus / clients début) | B14: 0.05
A16: Revenus
A17: Hausse de prix chaque année | B17: 0.2
A18: Mois d'ouverture des paiements B2C (0 = jamais) | B18: 0
A19: Part des boutiques qui activent le paiement en ligne | B19: 0
A20: Volume B2C encaissé par boutique active / mois (HT) | B20: 0
A21: Commission prélevée sur le volume B2C | B21: 0
A23: Fiscalité (à confirmer selon le pays)
A24: Taux de TVA / IVA (GE : 15 %) | B24: 0
A25: Part du CA soumise à TVA locale | B25: 1
A26: Part des achats avec TVA déductible | B26: 0
A27: Taux de l'impôt sur les sociétés (GE : 25 % depuis 2025) | B27: 0.25
A28: Minimum d'imposition (% du CA ; GE : 1,5 %) | B28: 0.015
A29: Mois de paiement de l'IS l'année suivante (1-12) | B29: 4
A30: Charges sociales patronales (% des salaires) | B30: 0.265
A32: Coûts directs
A33: Hébergement / infra fixe par mois | B33: 30000
A34: Infra variable par client / mois | B34: 100
A35: Frais de paiement (% des encaissements) | B35: 0.01
A37: Charges fixes
A38: Salaires bruts mensuels — année 1 | B38: 0
A39: Salaires bruts mensuels — année 2 | B39: 100000
A40: Salaires bruts mensuels — année 3 | B40: 200000
A41: Marketing fixe / mois | B41: 60000
A42: Coût d'acquisition par nouveau client (CAC) | B42: 5000
A43: Logiciels et outils / mois | B43: 30000
A44: Honoraires comptable / juridique / mois | B44: 10000
A45: Autres charges / mois | B45: 15000
A47: Investissement et financement
A48: Frais de création de la structure (charge du mois 1) | B48: 0
...

Sheet Mensuel
A1: Poste | B1: M1 | C1: M2 | D1: M3 | E1: M4 | F1: M5 | G1: M6 | H1: M7 | I1: M8 | J1: M9 | K1: M10 | L1: M11 | M1: M12 | N1: M13 | O1: M14 | P1: M15 | Q1: M16 | R1: M17 | S1: M18 | T1: M19 | U1: M20 | V1: M21 | W1: M22 | X1: M23 | Y1: M24 | Z1: M25 | AA1: M26 | AB1: M27 | AC1: M28 | AD1: M29 | AE1: M30 | AF1: M31 | AG1: M32 | AH1: M33 | AI1: M34 | AJ1: M35 | AK1: M36
A2: Mois n° | B2: 1 | C2: 2 | D2: 3 | E2: 4 | F2: 5 | G2: 6 | H2: 7 | I2: 8 | J2: 9 | K2: 10 | L2: 11 | M2: 12 | N2: 13 | O2: 14 | P2: 15 | Q2: 16 | R2: 17 | S2: 18 | T2: 19 | U2: 20 | V2: 21 | W2: 22 | X2: 23 | Y2: 24 | Z2: 25 | AA2: 26 | AB2: 27 | AC2: 28 | AD2: 29 | AE2: 30 | AF2: 31 | AG2: 32 | AH2: 33 | AI2: 34 | AJ2: 35 | AK2: 36
A3: Année | B3: =INT((B2-1)/12)+1 | C3: =INT((C2-1)/12)+1 | D3: =INT((D2-1)/12)+1 | E3: =INT((E2-1)/12)+1 | F3: =INT((F2-1)/12)+1 | G3: =INT((G2-1)/12)+1 | H3: =INT((H2-1)/12)+1 | I3: =INT((I2-1)/12)+1 | ... AK3: =INT((AK2-1)/12)+1
A4: Nouveaux clients | B4: =IF(B2<mois_lancement,0,nouveaux_m1*(1+croissance_acquisition)^(B2-mois_lancement)) | C4: =IF(C2<mois_lancement,0,nouveaux_m1*(1+croissance_acquisition)^(C2-mois_lancement)) | D4: =IF(D2<mois_lancement,0,nouveaux_m1*(1+croissance_acquisition)^(D2-mois_lancement)) | E4: =IF(E2<mois_lancement,0,nouveaux_m1*(1+croissance_acquisition)^(E2-mois_lancement)) | F4: =IF(F2<mois_lancement,0,nouveaux_m1*(1+croissance_acquisition)^(F2-mois_lancement)) | G4: =IF(G2<mois_lancement,0,nouveaux_m1*(1+croissance_acquisition)^(G2-mois_lancement)) | H4: =IF(H2<mois_lancement,0,nouveaux_m1*(1+croissance_acquisition)^(H2-mois_lancement)) | I4: =IF(I2<mois_lancement,0,nouveaux_m1*(1+croissance_acquisition)^(I2-mois_lancement)) | ... AK4: =IF(AK2<mois_lancement,0,nouveaux_m1*(1+croissance_acquisition)^(AK2-mois_lancement))
A5: Clients en début de mois | B5: =clients_initiaux | C5: =B7 | D5: =C7 | E5: =D7 | F5: =E7 | G5: =F7 | H5: =G7 | I5: =H7 | J5: =I7 | ... AK5: =AJ7
A6: Clients perdus (churn) | B6: =B5*churn_mensuel | C6: =C5*churn_mensuel | D6: =D5*churn_mensuel | E6: =E5*churn_mensuel | F6: =F5*churn_mensuel | G6: =G5*churn_mensuel | H6: =H5*churn_mensuel | I6: =I5*churn_mensuel | ... AK6: =AK5*churn_mensuel
A7: Clients en fin de mois | B7: =B5+B4-B6 | C7: =C5+C4-C6 | D7: =D5+D4-D6 | E7: =E5+E4-E6 | F7: =F5+F4-F6 | G7: =G5+G4-G6 | H7: =H5+H4-H6 | I7: =I5+I4-I6 | ... AK7: =AK5+AK4-AK6
A8: ARPA HT | B8: =arpa_base*(1+hausse_prix_annuelle)^(B3-1) | C8: =arpa_base*(1+hausse_prix_annuelle)^(C3-1) | D8: =arpa_base*(1+hausse_prix_annuelle)^(D3-1) | E8: =arpa_base*(1+hausse_prix_annuelle)^(E3-1) | F8: =arpa_base*(1+hausse_prix_annuelle)^(F3-1) | G8: =arpa_base*(1+hausse_prix_annuelle)^(G3-1) | H8: =arpa_base*(1+hausse_prix_annuelle)^(H3-1) | I8: =arpa_base*(1+hausse_prix_annuelle)^(I3-1) | ... AK8: =arpa_base*(1+hausse_prix_annuelle)^(AK3-1)
A9: MRR — CA abonnements HT | B9: =B7*B8 | C9: =C7*C8 | D9: =D7*D8 | E9: =E7*E8 | F9: =F7*F8 | G9: =G7*G8 | H9: =H7*H8 | I9: =I7*I8 | ... AK9: =AK7*AK8
A10: Commissions sur paiements B2C HT | B10: =IF(AND(mois_debut_paiements>0,B2>=mois_debut_paiements),B7*part_boutiques_paiement*volume_b2c_par_client*taux_commission,0) | C10: =IF(AND(mois_debut_paiements>0,C2>=mois_debut_paiements),C7*part_boutiques_paiement*volume_b2c_par_client*taux_commission,0) | D10: =IF(AND(mois_debut_paiements>0,D2>=mois_debut_paiements),D7*part_boutiques_paiement*volume_b2c_par_client*taux_commission,0) | E10: =IF(AND(mois_debut_paiements>0,E2>=mois_debut_paiements),E7*part_boutiques_paiement*volume_b2c_par_client*taux_commission,0) | F10: =IF(AND(mois_debut_paiements>0,F2>=mois_debut_paiements),F7*part_boutiques_paiement*volume_b2c_par_client*taux_commission,0) | G10: =IF(AND(mois_debut_paiements>0,G2>=mois_debut_paiements),G7*part_boutiques_paiement*volume_b2c_par_client*taux_commission,0) | H10: =IF(AND(mois_debut_paiements>0,H2>=mois_debut_paiements),H7*part_boutiques_paiement*volume_b2c_par_client*taux_commission,0) | I10: =IF(AND(mois_debut_paiements>0,I2>=mois_debut_paiements),I7*part_boutiques_paiement*volume_b2c_par_client*taux_commission,0) | ... AK10: =IF(AND(mois_debut_paiements>0,AK2>=mois_debut_paiements),AK7*part_boutiques_paiement*volume_b2c_par_client*taux_commission,0)
A11: CA total HT | B11: =B9+B10 | C11: =C9+C10 | D11: =D9+D10 | E11: =E9+E10 | F11: =F9+F10 | G11: =G9+G10 | H11: =H9+H10 | I11: =I9+I10 | ... AK11: =AK9+AK10
A12: TVA collectée | B12: =B11*taux_tva*part_ca_soumis_tva | C12: =C11*taux_tva*part_ca_soumis_tva | D12: =D11*taux_tva*part_ca_soumis_tva | E12: =E11*taux_tva*part_ca_soumis_tva | F12: =F11*taux_tva*part_ca_soumis_tva | G12: =G11*taux_tva*part_ca_soumis_tva | H12: =H11*taux_tva*part_ca_soumis_tva | I12: =I11*taux_tva*part_ca_soumis_tva | ... AK12: =AK11*taux_tva*part_ca_soumis_tva
A13: Encaissements TTC | B13: =B11+B12 | C13: =C11+C12 | D13: =D11+D12 | E13: =E11+E12 | F13: =F11+F12 | G13: =G11+G12 | H13: =H11+H12 | I13: =I11+I12 | ... AK13: =AK11+AK12
A14: Hébergement et infra | B14: =infra_fixe+infra_par_client*B7 | C14: =infra_fixe+infra_par_client*C7 | D14: =infra_fixe+infra_par_client*D7 | E14: =infra_fixe+infra_par_client*E7 | F14: =infra_fixe+infra_par_client*F7 | G14: =infra_fixe+infra_par_client*G7 | H14: =infra_fixe+infra_par_client*H7 | I14: =infra_fixe+infra_par_client*I7 | ... AK14: =infra_fixe+infra_par_client*AK7
A15: Frais de paiement | B15: =B13*taux_frais_paiement | C15: =C13*taux_frais_paiement | D15: =D13*taux_frais_paiement | E15: =E13*taux_frais_paiement | F15: =F13*taux_frais_paiement | G15: =G13*taux_frais_paiement | H15: =H13*taux_frais_paiement | I15: =I13*taux_frais_paiement | ... AK15: =AK13*taux_frais_paiement
A16: Marge brute | B16: =B11-B14-B15 | C16: =C11-C14-C15 | D16: =D11-D14-D15 | E16: =E11-E14-E15 | F16: =F11-F14-F15 | G16: =G11-G14-G15 | H16: =H11-H14-H15 | I16: =I11-I14-I15 | ... AK16: =AK11-AK14-AK15
A17: Taux de marge brute | B17: =IF(B11=0,0,B16/B11) | C17: =IF(C11=0,0,C16/C11) | D17: =IF(D11=0,0,D16/D11) | E17: =IF(E11=0,0,E16/E11) | F17: =IF(F11=0,0,F16/F11) | G17: =IF(G11=0,0,G16/G11) | H17: =IF(H11=0,0,H16/H11) | I17: =IF(I11=0,0,I16/I11) | ... AK17: =IF(AK11=0,0,AK16/AK11)
A18: Salaires bruts | B18: =CHOOSE(B3,salaires_an1,salaires_an2,salaires_an3) | C18: =CHOOSE(C3,salaires_an1,salaires_an2,salaires_an3) | D18: =CHOOSE(D3,salaires_an1,salaires_an2,salaires_an3) | E18: =CHOOSE(E3,salaires_an1,salaires_an2,salaires_an3) | F18: =CHOOSE(F3,salaires_an1,salaires_an2,salaires_an3) | G18: =CHOOSE(G3,salaires_an1,salaires_an2,salaires_an3) | H18: =CHOOSE(H3,salaires_an1,salaires_an2,salaires_an3) | I18: =CHOOSE(I3,salaires_an1,salaires_an2,salaires_an3) | ... AK18: =CHOOSE(AK3,salaires_an1,salaires_an2,salaires_an3)
A19: Charges sociales | B19: =B18*taux_charges_sociales | C19: =C18*taux_charges_sociales | D19: =D18*taux_charges_sociales | E19: =E18*taux_charges_sociales | F19: =F18*taux_charges_sociales | G19: =G18*taux_charges_sociales | H19: =H18*taux_charges_sociales | I19: =I18*taux_charges_sociales | ... AK19: =AK18*taux_charges_sociales
A20: Marketing et acquisition | B20: =marketing_fixe+cac*B4 | C20: =marketing_fixe+cac*C4 | D20: =marketing_fixe+cac*D4 | E20: =marketing_fixe+cac*E4 | F20: =marketing_fixe+cac*F4 | G20: =marketing_fixe+cac*G4 | H20: =marketing_fixe+cac*H4 | I20: =marketing_fixe+cac*I4 | ... AK20: =marketing_fixe+cac*AK4
A21: Logiciels et outils | B21: =outils_mensuels | C21: =outils_mensuels | D21: =outils_mensuels | E21: =outils_mensuels | F21: =outils_mensuels | G21: =outils_mensuels | H21: =outils_mensuels | I21: =outils_mensuels | ... AK21: =outils_mensuels
A22: Honoraires | B22: =honoraires_mensuels | C22: =honoraires_mensuels | D22: =honoraires_mensuels | E22: =honoraires_mensuels | F22: =honoraires_mensuels | G22: =honoraires_mensuels | H22: =honoraires_mensuels | I22: =honoraires_mensuels | ... AK22: =honoraires_mensuels
A23: Autres charges (dont frais de création au mois 1) | B23: =autres_mensuelles+IF(B2=1,frais_creation,0) | C23: =autres_mensuelles+IF(C2=1,frais_creation,0) | D23: =autres_mensuelles+IF(D2=1,frais_creation,0) | E23: =autres_mensuelles+IF(E2=1,frais_creation,0) | F23: =autres_mensuelles+IF(F2=1,frais_creation,0) | G23: =autres_mensuelles+IF(G2=1,frais_creation,0) | H23: =autres_mensuelles+IF(H2=1,frais_creation,0) | I23: =autres_mensuelles+IF(I2=1,frais_creation,0) | ... AK23: =autres_mensuelles+IF(AK2=1,frais_creation,0)
A24: Total charges d'exploitation | B24: =SUM(B18:B23) | C24: =SUM(C18:C23) | D24: =SUM(D18:D23) | E24: =SUM(E18:E23) | F24: =SUM(F18:F23) | G24: =SUM(G18:G23) | H24: =SUM(H18:H23) | I24: =SUM(I18:I23) | ... AK24: =SUM(AK18:AK23)
A25: EBE (excédent brut d'exploitation) | B25: =B16-B24 | C25: =C16-C24 | D25: =D16-D24 | E25: =E16-E24 | F25: =F16-F24 | G25: =G16-G24 | H25: =H16-H24 | I25: =I16-I24 | ... AK25: =AK16-AK24
A26: TVA déductible | B26: =(B14+B20+B21+B22+B23)*taux_tva*part_achats_avec_tva | C26: =(C14+C20+C21+C22+C23)*taux_tva*part_achats_avec_tva | D26: =(D14+D20+D21+D22+D23)*taux_tva*part_achats_avec_tva | E26: =(E14+E20+E21+E22+E23)*taux_tva*part_achats_avec_tva | F26: =(F14+F20+F21+F22+F23)*taux_tva*part_achats_avec_tva | G26: =(G14+G20+G21+G22+G23)*taux_tva*part_achats_avec_tva | H26: =(H14+H20+H21+H22+H23)*taux_tva*part_achats_avec_tva | I26: =(I14+I20+I21+I22+I23)*taux_tva*part_achats_avec_tva | ... AK26: =(AK14+AK20+AK21+AK22+AK23)*taux_tva*part_achats_avec_tva
A27: TVA nette du mois (collectée − déductible) | B27: =B12-B26 | C27: =C12-C26 | D27: =D12-D26 | E27: =E12-E26 | F27: =F12-F26 | G27: =G12-G26 | H27: =H12-H26 | I27: =I12-I26 | ... AK27: =AK12-AK26
A28: TVA reversée (le mois suivant) | B28: 0 | C28: =MAX(0,B27) | D28: =MAX(0,C27) | E28: =MAX(0,D27) | F28: =MAX(0,E27) | G28: =MAX(0,F27) | H28: =MAX(0,G27) | I28: =MAX(0,H27) | J28: =MAX(0,I27) | ... AK28: =MAX(0,AJ27)
A29: IS payé | B29: =IF(AND(B3>1,MOD(B2-1,12)+1=mois_paiement_is),INDEX(Annuel!$B$13:$D$13,B3-1),0) | C29: =IF(AND(C3>1,MOD(C2-1,12)+1=mois_paiement_is),INDEX(Annuel!$B$13:$D$13,C3-1),0) | D29: =IF(AND(D3>1,MOD(D2-1,12)+1=mois_paiement_is),INDEX(Annuel!$B$13:$D$13,D3-1),0) | E29: =IF(AND(E3>1,MOD(E2-1,12)+1=mois_paiement_is),INDEX(Annuel!$B$13:$D$13,E3-1),0) | F29: =IF(AND(F3>1,MOD(F2-1,12)+1=mois_paiement_is),INDEX(Annuel!$B$13:$D$13,F3-1),0) | G29: =IF(AND(G3>1,MOD(G2-1,12)+1=mois_paiement_is),INDEX(Annuel!$B$13:$D$13,G3-1),0) | H29: =IF(AND(H3>1,MOD(H2-1,12)+1=mois_paiement_is),INDEX(Annuel!$B$13:$D$13,H3-1),0) | I29: =IF(AND(I3>1,MOD(I2-1,12)+1=mois_paiement_is),INDEX(Annuel!$B$13:$D$13,I3-1),0) | ... AK29: =IF(AND(AK3>1,MOD(AK2-1,12)+1=mois_paiement_is),INDEX(Annuel!$B$13:$D$13,AK3-1),0)
A30: Investissements | B30: =IF(B2=1,investissement_initial,0) | C30: =IF(C2=1,investissement_initial,0) | D30: =IF(D2=1,investissement_initial,0) | E30: =IF(E2=1,investissement_initial,0) | F30: =IF(F2=1,investissement_initial,0) | G30: =IF(G2=1,investissement_initial,0) | H30: =IF(H2=1,investissement_initial,0) | I30: =IF(I2=1,investissement_initial,0) | ... AK30: =IF(AK2=1,investissement_initial,0)
A31: Total décaissements | B31: =B14+B15+B18+B19+B20+B21+B22+B23+B28+B29+B30 | C31: =C14+C15+C18+C19+C20+C21+C22+C23+C28+C29+C30 | D31: =D14+D15+D18+D19+D20+D21+D22+D23+D28+D29+D30 | E31: =E14+E15+E18+E19+E20+E21+E22+E23+E28+E29+E30 | F31: =F14+F15+F18+F19+F20+F21+F22+F23+F28+F29+F30 | G31: =G14+G15+G18+G19+G20+G21+G22+G23+G28+G29+G30 | H31: =H14+H15+H18+H19+H20+H21+H22+H23+H28+H29+H30 | I31: =I14+I15+I18+I19+I20+I21+I22+I23+I28+I29+I30 | ... AK31: =AK14+AK15+AK18+AK19+AK20+AK21+AK22+AK23+AK28+AK29+AK30
A32: Flux de trésorerie net | B32: =B13-B31 | C32: =C13-C31 | D32: =D13-D31 | E32: =E13-E31 | F32: =F13-F31 | G32: =G13-G31 | H32: =H13-H31 | I32: =I13-I31 | ... AK32: =AK13-AK31
A33: Trésorerie en fin de mois | B33: =apport_initial+B32 | C33: =B33+C32 | D33: =C33+D32 | E33: =D33+E32 | F33: =E33+F32 | G33: =F33+G32 | H33: =G33+H32 | I33: =H33+I32 | J33: =I33+J32 | ... AK33: =AJ33+AK32

Sheet Annuel
A1: Année | B1: 1 | C1: 2 | D1: 3
A2: CA abonnements HT | B2: =SUMIF(Mensuel!$B$3:$AK$3,B$1,Mensuel!$B$9:$AK$9) | C2: =SUMIF(Mensuel!$B$3:$AK$3,C$1,Mensuel!$B$9:$AK$9) | D2: =SUMIF(Mensuel!$B$3:$AK$3,D$1,Mensuel!$B$9:$AK$9)
A3: Commissions B2C HT | B3: =SUMIF(Mensuel!$B$3:$AK$3,B$1,Mensuel!$B$10:$AK$10) | C3: =SUMIF(Mensuel!$B$3:$AK$3,C$1,Mensuel!$B$10:$AK$10) | D3: =SUMIF(Mensuel!$B$3:$AK$3,D$1,Mensuel!$B$10:$AK$10)
A4: CA total HT | B4: =SUMIF(Mensuel!$B$3:$AK$3,B$1,Mensuel!$B$11:$AK$11) | C4: =SUMIF(Mensuel!$B$3:$AK$3,C$1,Mensuel!$B$11:$AK$11) | D4: =SUMIF(Mensuel!$B$3:$AK$3,D$1,Mensuel!$B$11:$AK$11)
A5: Marge brute | B5: =SUMIF(Mensuel!$B$3:$AK$3,B$1,Mensuel!$B$16:$AK$16) | C5: =SUMIF(Mensuel!$B$3:$AK$3,C$1,Mensuel!$B$16:$AK$16) | D5: =SUMIF(Mensuel!$B$3:$AK$3,D$1,Mensuel!$B$16:$AK$16)
A6: Charges d'exploitation | B6: =SUMIF(Mensuel!$B$3:$AK$3,B$1,Mensuel!$B$24:$AK$24) | C6: =SUMIF(Mensuel!$B$3:$AK$3,C$1,Mensuel!$B$24:$AK$24) | D6: =SUMIF(Mensuel!$B$3:$AK$3,D$1,Mensuel!$B$24:$AK$24)
A7: EBE | B7: =SUMIF(Mensuel!$B$3:$AK$3,B$1,Mensuel!$B$25:$AK$25) | C7: =SUMIF(Mensuel!$B$3:$AK$3,C$1,Mensuel!$B$25:$AK$25) | D7: =SUMIF(Mensuel!$B$3:$AK$3,D$1,Mensuel!$B$25:$AK$25)
A8: Dotations aux amortissements | B8: =IF(B1<=duree_amortissement,investissement_initial/duree_amortissement,0) | C8: =IF(C1<=duree_amortissement,investissement_initial/duree_amortissement,0) | D8: =IF(D1<=duree_amortissement,investissement_initial/duree_amortissement,0)
A9: Résultat avant impôt | B9: =B7-B8 | C9: =C7-C8 | D9: =D7-D8
A10: IS théorique (taux × base imposable après report des déficits) | B10: =B21*taux_is | C10: =C21*taux_is | D10: =D21*taux_is
A11: Minimum d'imposition (% du CA) | B11: =B4*taux_minimum_is | C11: =C4*taux_minimum_is | D11: =D4*taux_minimum_is
A13: IS dû (le plus élevé des deux) | B13: =MAX(B10,B11) | C13: =MAX(C10,C11) | D13: =MAX(D10,D11)
A14: Résultat net | B14: =B9-B13 | C14: =C9-C13 | D14: =D9-D13
A15: Clients en fin d'année | B15: =INDEX(Mensuel!$B$7:$AK$7,B1*12) | C15: =INDEX(Mensuel!$B$7:$AK$7,C1*12) | D15: =INDEX(Mensuel!$B$7:$AK$7,D1*12)
A16: MRR en fin d'année | B16: =INDEX(Mensuel!$B$9:$AK$9,B1*12) | C16: =INDEX(Mensuel!$B$9:$AK$9,C1*12) | D16: =INDEX(Mensuel!$B$9:$AK$9,D1*12)
A17: ARR en fin d'année | B17: =B16*12 | C17: =C16*12 | D17: =D16*12
A18: Trésorerie en fin d'année | B18: =INDEX(Mensuel!$B$33:$AK$33,B1*12) | C18: =INDEX(Mensuel!$B$33:$AK$33,C1*12) | D18: =INDEX(Mensuel!$B$33:$AK$33,D1*12)
A19: Déficits reportables à l'ouverture | B19: =0 | C19: =B20 | D19: =C20
A20: Déficits reportables à la clôture | B20: =MAX(0,B19-B9) | C20: =MAX(0,C19-C9) | D20: =MAX(0,D19-D9)
A21: Base imposable après report | B21: =MAX(0,B9-B19) | C21: =MAX(0,C9-C19) | D21: =MAX(0,D9-D19)
A23: Simplifications : TVA reversée le mois suivant (crédits de TVA non reportés), IS payé en une fois l'année suivante, pas d'acomptes, déficits reportables sans limite de durée sur 3 ans. Ajuste selon le pays.

Sheet Tableau de bord
A1: Tableau de bord
A3: ARR fin année 1 | B3: =Annuel!B17
A4: ARR fin année 3 | B4: =Annuel!D17
A5: Clients fin année 3 | B5: =Annuel!D15
A6: Résultat net cumulé 3 ans | B6: =SUM(Annuel!B14:D14)
A7: Trésorerie la plus basse | B7: =MIN(Mensuel!B33:AK33)
A8: Mois de la trésorerie la plus basse | B8: =INDEX(Mensuel!B2:AK2,MATCH(MIN(Mensuel!B33:AK33),Mensuel!B33:AK33,0))
A9: Premier mois avec EBE positif | B9: =IFERROR(INDEX(Mensuel!B2:AK2,MATCH(TRUE,INDEX(Mensuel!B25:AK25>0,0),0)),"Non atteint")
A10: LTV (ARPA × marge brute ÷ churn) | B10: =IF(churn_mensuel=0,"n/a",arpa_base*AVERAGE(Mensuel!M17:AK17)/churn_mensuel)
A11: LTV / CAC | B11: =IF(OR(cac=0,churn_mensuel=0),"n/a",B10/cac)
A13: Trésorerie négative = besoin de financement : augmente l'apport ou revois les hypothèses.
